Workbook

Sheet Weekly
A1: Lane Tracker
A2: Lane | B2: Last PM Date | C2: Pin Count | D2: Ball Damage | E2: 180 | F2: Blackout | G2: Ball Return | H2: Respot | I2: Other | J2: Weekly Total | L2: Weekly Combined Total: | M2: =SUM(J3:J58) -> 0
A3: 1 | D3: No | E3: =SUM(Daily!B3,Daily!B62,Daily!B121,Daily!B180,Daily!B239,Daily!B298,Daily!B357) -> 0 | F3: =SUM(Daily!C3,Daily!C62,Daily!C121,Daily!C180,Daily!C239,Daily!C298,Daily!C357) -> 0 | G3: =SUM(Daily!D3,Daily!D62,Daily!D121,Daily!D180,Daily!D239,Daily!D298,Daily!D357) -> 0 | H3: =SUM(Daily!E3,Daily!E62,Daily!E121,Daily!E180,Daily!E239,Daily!E298,Daily!E357) -> 0 | I3: =SUM(Daily!F3,Daily!F62,Daily!F121,Daily!F180,Daily!F239,Daily!F298,Daily!F357) -> 0 | J3: =SUM(E3:I3) -> 0 | L3: Weekly Games: | M3: =SUM(Daily!J3,Daily!J62,Daily!J121,Daily!J180,Daily!J239,Daily!J298,Daily!J357) -> 0
A4: 2 | D4: No | E4: =SUM(Daily!B4,Daily!B63,Daily!B122,Daily!B181,Daily!B240,Daily!B299,Daily!B358) -> 0 | F4: =SUM(Daily!C4,Daily!C63,Daily!C122,Daily!C181,Daily!C240,Daily!C299,Daily!C358) -> 0 | G4: =SUM(Daily!D4,Daily!D63,Daily!D122,Daily!D181,Daily!D240,Daily!D299,Daily!D358) -> 0 | H4: =SUM(Daily!E4,Daily!E63,Daily!E122,Daily!E181,Daily!E240,Daily!E299,Daily!E358) -> 0 | I4: =SUM(Daily!F4,Daily!F63,Daily!F122,Daily!F181,Daily!F240,Daily!F299,Daily!F358) -> 0 | J4: =SUM(E4:I4) -> 0 | L4: Weekly FPS: | M4: =(M3*10)/M2 -> #DIV/0!
A5: 3 | D5: No | E5: =SUM(Daily!B5,Daily!B64,Daily!B123,Daily!B182,Daily!B241,Daily!B300,Daily!B359) -> 0 | F5: =SUM(Daily!C5,Daily!C64,Daily!C123,Daily!C182,Daily!C241,Daily!C300,Daily!C359) -> 0 | G5: =SUM(Daily!D5,Daily!D64,Daily!D123,Daily!D182,Daily!D241,Daily!D300,Daily!D359) -> 0 | H5: =SUM(Daily!E5,Daily!E64,Daily!E123,Daily!E182,Daily!E241,Daily!E300,Daily!E359) -> 0 | I5: =SUM(Daily!F5,Daily!F64,Daily!F123,Daily!F182,Daily!F241,Daily!F300,Daily!F359) -> 0 | J5: =SUM(E5:I5) -> 0
A6: 4 | D6: No | E6: =SUM(Daily!B6,Daily!B65,Daily!B124,Daily!B183,Daily!B242,Daily!B301,Daily!B360) -> 0 | F6: =SUM(Daily!C6,Daily!C65,Daily!C124,Daily!C183,Daily!C242,Daily!C301,Daily!C360) -> 0 | G6: =SUM(Daily!D6,Daily!D65,Daily!D124,Daily!D183,Daily!D242,Daily!D301,Daily!D360) -> 0 | H6: =SUM(Daily!E6,Daily!E65,Daily!E124,Daily!E183,Daily!E242,Daily!E301,Daily!E360) -> 0 | I6: =SUM(Daily!F6,Daily!F65,Daily!F124,Daily!F183,Daily!F242,Daily!F301,Daily!F360) -> 0 | J6: =SUM(E6:I6) -> 0
A7: 5 | D7: No | E7: =SUM(Daily!B7,Daily!B66,Daily!B125,Daily!B184,Daily!B243,Daily!B302,Daily!B361) -> 0 | F7: =SUM(Daily!C7,Daily!C66,Daily!C125,Daily!C184,Daily!C243,Daily!C302,Daily!C361) -> 0 | G7: =SUM(Daily!D7,Daily!D66,Daily!D125,Daily!D184,Daily!D243,Daily!D302,Daily!D361) -> 0 | H7: =SUM(Daily!E7,Daily!E66,Daily!E125,Daily!E184,Daily!E243,Daily!E302,Daily!E361) -> 0 | I7: =SUM(Daily!F7,Daily!F66,Daily!F125,Daily!F184,Daily!F243,Daily!F302,Daily!F361) -> 0 | J7: =SUM(E7:I7) -> 0
A8: 6 | D8: No | E8: =SUM(Daily!B8,Daily!B67,Daily!B126,Daily!B185,Daily!B244,Daily!B303,Daily!B362) -> 0 | F8: =SUM(Daily!C8,Daily!C67,Daily!C126,Daily!C185,Daily!C244,Daily!C303,Daily!C362) -> 0 | G8: =SUM(Daily!D8,Daily!D67,Daily!D126,Daily!D185,Daily!D244,Daily!D303,Daily!D362) -> 0 | H8: =SUM(Daily!E8,Daily!E67,Daily!E126,Daily!E185,Daily!E244,Daily!E303,Daily!E362) -> 0 | I8: =SUM(Daily!F8,Daily!F67,Daily!F126,Daily!F185,Daily!F244,Daily!F303,Daily!F362) -> 0 | J8: =SUM(E8:I8) -> 0
A9: 7 | D9: No | E9: =SUM(Daily!B9,Daily!B68,Daily!B127,Daily!B186,Daily!B245,Daily!B304,Daily!B363) -> 0 | F9: =SUM(Daily!C9,Daily!C68,Daily!C127,Daily!C186,Daily!C245,Daily!C304,Daily!C363) -> 0 | G9: =SUM(Daily!D9,Daily!D68,Daily!D127,Daily!D186,Daily!D245,Daily!D304,Daily!D363) -> 0 | H9: =SUM(Daily!E9,Daily!E68,Daily!E127,Daily!E186,Daily!E245,Daily!E304,Daily!E363) -> 0 | I9: =SUM(Daily!F9,Daily!F68,Daily!F127,Daily!F186,Daily!F245,Daily!F304,Daily!F363) -> 0 | J9: =SUM(E9:I9) -> 0
A10: 8 | D10: No | E10: =SUM(Daily!B10,Daily!B69,Daily!B128,Daily!B187,Daily!B246,Daily!B305,Daily!B364) -> 0 | F10: =SUM(Daily!C10,Daily!C69,Daily!C128,Daily!C187,Daily!C246,Daily!C305,Daily!C364) -> 0 | G10: =SUM(Daily!D10,Daily!D69,Daily!D128,Daily!D187,Daily!D246,Daily!D305,Daily!D364) -> 0 | H10: =SUM(Daily!E10,Daily!E69,Daily!E128,Daily!E187,Daily!E246,Daily!E305,Daily!E364) -> 0 | I10: =SUM(Daily!F10,Daily!F69,Daily!F128,Daily!F187,Daily!F246,Daily!F305,Daily!F364) -> 0 | J10: =SUM(E10:I10) -> 0
A11: 9 | D11: No | E11: =SUM(Daily!B11,Daily!B70,Daily!B129,Daily!B188,Daily!B247,Daily!B306,Daily!B365) -> 0 | F11: =SUM(Daily!C11,Daily!C70,Daily!C129,Daily!C188,Daily!C247,Daily!C306,Daily!C365) -> 0 | G11: =SUM(Daily!D11,Daily!D70,Daily!D129,Daily!D188,Daily!D247,Daily!D306,Daily!D365) -> 0 | H11: =SUM(Daily!E11,Daily!E70,Daily!E129,Daily!E188,Daily!E247,Daily!E306,Daily!E365) -> 0 | I11: =SUM(Daily!F11,Daily!F70,Daily!F129,Daily!F188,Daily!F247,Daily!F306,Daily!F365) -> 0 | J11: =SUM(E11:I11) -> 0
A12: 10 | D12: No | E12: =SUM(Daily!B12,Daily!B71,Daily!B130,Daily!B189,Daily!B248,Daily!B307,Daily!B366) -> 0 | F12: =SUM(Daily!C12,Daily!C71,Daily!C130,Daily!C189,Daily!C248,Daily!C307,Daily!C366) -> 0 | G12: =SUM(Daily!D12,Daily!D71,Daily!D130,Daily!D189,Daily!D248,Daily!D307,Daily!D366) -> 0 | H12: =SUM(Daily!E12,Daily!E71,Daily!E130,Daily!E189,Daily!E248,Daily!E307,Daily!E366) -> 0 | I12: =SUM(Daily!F12,Daily!F71,Daily!F130,Daily!F189,Daily!F248,Daily!F307,Daily!F366) -> 0 | J12: =SUM(E12:I12) -> 0
A13: 11 | D13: No | E13: =SUM(Daily!B13,Daily!B72,Daily!B131,Daily!B190,Daily!B249,Daily!B308,Daily!B367) -> 0 | F13: =SUM(Daily!C13,Daily!C72,Daily!C131,Daily!C190,Daily!C249,Daily!C308,Daily!C367) -> 0 | G13: =SUM(Daily!D13,Daily!D72,Daily!D131,Daily!D190,Daily!D249,Daily!D308,Daily!D367) -> 0 | H13: =SUM(Daily!E13,Daily!E72,Daily!E131,Daily!E190,Daily!E249,Daily!E308,Daily!E367) -> 0 | I13: =SUM(Daily!F13,Daily!F72,Daily!F131,Daily!F190,Daily!F249,Daily!F308,Daily!F367) -> 0 | J13: =SUM(E13:I13) -> 0
A14: 12 | D14: No | E14: =SUM(Daily!B14,Daily!B73,Daily!B132,Daily!B191,Daily!B250,Daily!B309,Daily!B368) -> 0 | F14: =SUM(Daily!C14,Daily!C73,Daily!C132,Daily!C191,Daily!C250,Daily!C309,Daily!C368) -> 0 | G14: =SUM(Daily!D14,Daily!D73,Daily!D132,Daily!D191,Daily!D250,Daily!D309,Daily!D368) -> 0 | H14: =SUM(Daily!E14,Daily!E73,Daily!E132,Daily!E191,Daily!E250,Daily!E309,Daily!E368) -> 0 | I14: =SUM(Daily!F14,Daily!F73,Daily!F132,Daily!F191,Daily!F250,Daily!F309,Daily!F368) -> 0 | J14: =SUM(E14:I14) -> 0
A15: 13 | D15: No | E15: =SUM(Daily!B15,Daily!B74,Daily!B133,Daily!B192,Daily!B251,Daily!B310,Daily!B369) -> 0 | F15: =SUM(Daily!C15,Daily!C74,Daily!C133,Daily!C192,Daily!C251,Daily!C310,Daily!C369) -> 0 | G15: =SUM(Daily!D15,Daily!D74,Daily!D133,Daily!D192,Daily!D251,Daily!D310,Daily!D369) -> 0 | H15: =SUM(Daily!E15,Daily!E74,Daily!E133,Daily!E192,Daily!E251,Daily!E310,Daily!E369) -> 0 | I15: =SUM(Daily!F15,Daily!F74,Daily!F133,Daily!F192,Daily!F251,Daily!F310,Daily!F369) -> 0 | J15: =SUM(E15:I15) -> 0
A16: 14 | D16: No | E16: =SUM(Daily!B16,Daily!B75,Daily!B134,Daily!B193,Daily!B252,Daily!B311,Daily!B370) -> 0 | F16: =SUM(Daily!C16,Daily!C75,Daily!C134,Daily!C193,Daily!C252,Daily!C311,Daily!C370) -> 0 | G16: =SUM(Daily!D16,Daily!D75,Daily!D134,Daily!D193,Daily!D252,Daily!D311,Daily!D370) -> 0 | H16: =SUM(Daily!E16,Daily!E75,Daily!E134,Daily!E193,Daily!E252,Daily!E311,Daily!E370) -> 0 | I16: =SUM(Daily!F16,Daily!F75,Daily!F134,Daily!F193,Daily!F252,Daily!F311,Daily!F370) -> 0 | J16: =SUM(E16:I16) -> 0
... A58: 56 | D58: No | E58: =SUM(Daily!B58,Daily!B117,Daily!B176,Daily!B235,Daily!B294,Daily!B353,Daily!B412) -> 0 | F58: =SUM(Daily!C58,Daily!C117,Daily!C176,Daily!C235,Daily!C294,Daily!C353,Daily!C412) -> 0 | G58: =SUM(Daily!D58,Daily!D117,Daily!D176,Daily!D235,Daily!D294,Daily!D353,Daily!D412) -> 0 | H58: =SUM(Daily!E58,Daily!E117,Daily!E176,Daily!E235,Daily!E294,Daily!E353,Daily!E412) -> 0 | I58: =SUM(Daily!F58,Daily!F117,Daily!F176,Daily!F235,Daily!F294,Daily!F353,Daily!F412) -> 0 | J58: =SUM(E58:I58) -> 0
A61: Weekly Total | B61: 180 | I61: Black Out | M61: Ball Return | Y61: Other
A62: Lane | B62: Ball Blocking Pins | C62: Pin Guide Jam | D62: Turn Pan Jam | E62: Pin Gate Locked | F62: Pin Head First | G62: Turret Jam | H62: Other | I62: Deck Jam | J62: Turn Pan Jam | K62: Electrical | L62: Other | M62: Pins Blocking Ball | N62: Spinning | O62: Under Elbow | P62: In Pin Wheel | Q62: Between Lift Rod & Pit Cushion | R62: Yo-Yo | S62: Top Of Lift Rod | T62: Locked @ Pref | U62: Pin in Return Track | V62: @Y | W62: In Front of Pit Cushion | X62: Other | Y62: Respot | Z62: Other
A63: 1 | B63: =SUM(Monday!B4,Tuesday!B4,Wednesday!B4,Thursday!B4,Friday!B4,Saturday!B4,Sunday!B4) -> 0 | C63: =SUM(Monday!C4,Tuesday!C4,Wednesday!C4,Thursday!C4,Friday!C4,Saturday!C4,Sunday!C4) -> 0 | D63: =SUM(Monday!D4,Tuesday!D4,Wednesday!D4,Thursday!D4,Friday!D4,Saturday!D4,Sunday!D4) -> 0 | E63: =SUM(Monday!E4,Tuesday!E4,Wednesday!E4,Thursday!E4,Friday!E4,Saturday!E4,Sunday!E4) -> 0 | F63: =SUM(Monday!F4,Tuesday!F4,Wednesday!F4,Thursday!F4,Friday!F4,Saturday!F4,Sunday!F4) -> 0 | G63: =SUM(Monday!G4,Tuesday!G4,Wednesday!G4,Thursday!G4,Friday!G4,Saturday!G4,Sunday!G4) -> 0 | H63: =SUM(Monday!H4,Tuesday!H4,Wednesday!H4,Thursday!H4,Friday!H4,Saturday!H4,Sunday!H4) -> 0 | I63: =SUM(Monday!I4,Tuesday!I4,Wednesday!I4,Thursday!I4,Friday!I4,Saturday!I4,Sunday!I4) -> 0 | ... Z63: =SUM(Monday!Z4,Tuesday!Z4,Wednesday!Z4,Thursday!Z4,Friday!Z4,Saturday!Z4,Sunday!Z4) -> 0
A64: 2 | B64: =SUM(Monday!B5,Tuesday!B5,Wednesday!B5,Thursday!B5,Friday!B5,Saturday!B5,Sunday!B5) -> 0 | C64: =SUM(Monday!C5,Tuesday!C5,Wednesday!C5,Thursday!C5,Friday!C5,Saturday!C5,Sunday!C5) -> 0 | D64: =SUM(Monday!D5,Tuesday!D5,Wednesday!D5,Thursday!D5,Friday!D5,Saturday!D5,Sunday!D5) -> 0 | E64: =SUM(Monday!E5,Tuesday!E5,Wednesday!E5,Thursday!E5,Friday!E5,Saturday!E5,Sunday!E5) -> 0 | F64: =SUM(Monday!F5,Tuesday!F5,Wednesday!F5,Thursday!F5,Friday!F5,Saturday!F5,Sunday!F5) -> 0 | G64: =SUM(Monday!G5,Tuesday!G5,Wednesday!G5,Thursday!G5,Friday!G5,Saturday!G5,Sunday!G5) -> 0 | H64: =SUM(Monday!H5,Tuesday!H5,Wednesday!H5,Thursday!H5,Friday!H5,Saturday!H5,Sunday!H5) -> 0 | I64: =SUM(Monday!I5,Tuesday!I5,Wednesday!I5,Thursday!I5,Friday!I5,Saturday!I5,Sunday!I5) -> 0 | ... Z64: =SUM(Monday!Z5,Tuesday!Z5,Wednesday!Z5,Thursday!Z5,Friday!Z5,Saturday!Z5,Sunday!Z5) -> 0
A65: 3 | B65: =SUM(Monday!B6,Tuesday!B6,Wednesday!B6,Thursday!B6,Friday!B6,Saturday!B6,Sunday!B6) -> 0 | C65: =SUM(Monday!C6,Tuesday!C6,Wednesday!C6,Thursday!C6,Friday!C6,Saturday!C6,Sunday!C6) -> 0 | D65: =SUM(Monday!D6,Tuesday!D6,Wednesday!D6,Thursday!D6,Friday!D6,Saturday!D6,Sunday!D6) -> 0 | E65: =SUM(Monday!E6,Tuesday!E6,Wednesday!E6,Thursday!E6,Friday!E6,Saturday!E6,Sunday!E6) -> 0 | F65: =SUM(Monday!F6,Tuesday!F6,Wednesday!F6,Thursday!F6,Friday!F6,Saturday!F6,Sunday!F6) -> 0 | G65: =SUM(Monday!G6,Tuesday!G6,Wednesday!G6,Thursday!G6,Friday!G6,Saturday!G6,Sunday!G6) -> 0 | H65: =SUM(Monday!H6,Tuesday!H6,Wednesday!H6,Thursday!H6,Friday!H6,Saturday!H6,Sunday!H6) -> 0 | I65: =SUM(Monday!I6,Tuesday!I6,Wednesday!I6,Thursday!I6,Friday!I6,Saturday!I6,Sunday!I6) -> 0 | ... Z65: =SUM(Monday!Z6,Tuesday!Z6,Wednesday!Z6,Thursday!Z6,Friday!Z6,Saturday!Z6,Sunday!Z6) -> 0
A66: 4 | B66: =SUM(Monday!B7,Tuesday!B7,Wednesday!B7,Thursday!B7,Friday!B7,Saturday!B7,Sunday!B7) -> 0 | C66: =SUM(Monday!C7,Tuesday!C7,Wednesday!C7,Thursday!C7,Friday!C7,Saturday!C7,Sunday!C7) -> 0 | D66: =SUM(Monday!D7,Tuesday!D7,Wednesday!D7,Thursday!D7,Friday!D7,Saturday!D7,Sunday!D7) -> 0 | E66: =SUM(Monday!E7,Tuesday!E7,Wednesday!E7,Thursday!E7,Friday!E7,Saturday!E7,Sunday!E7) -> 0 | F66: =SUM(Monday!F7,Tuesday!F7,Wednesday!F7,Thursday!F7,Friday!F7,Saturday!F7,Sunday!F7) -> 0 | G66: =SUM(Monday!G7,Tuesday!G7,Wednesday!G7,Thursday!G7,Friday!G7,Saturday!G7,Sunday!G7) -> 0 | H66: =SUM(Monday!H7,Tuesday!H7,Wednesday!H7,Thursday!H7,Friday!H7,Saturday!H7,Sunday!H7) -> 0 | I66: =SUM(Monday!I7,Tuesday!I7,Wednesday!I7,Thursday!I7,Friday!I7,Saturday!I7,Sunday!I7) -> 0 | ... Z66: =SUM(Monday!Z7,Tuesday!Z7,Wednesday!Z7,Thursday!Z7,Friday!Z7,Saturday!Z7,Sunday!Z7) -> 0
A67: 5 | B67: =SUM(Monday!B8,Tuesday!B8,Wednesday!B8,Thursday!B8,Friday!B8,Saturday!B8,Sunday!B8) -> 0 | C67: =SUM(Monday!C8,Tuesday!C8,Wednesday!C8,Thursday!C8,Friday!C8,Saturday!C8,Sunday!C8) -> 0 | D67: =SUM(Monday!D8,Tuesday!D8,Wednesday!D8,Thursday!D8,Friday!D8,Saturday!D8,Sunday!D8) -> 0 | E67: =SUM(Monday!E8,Tuesday!E8,Wednesday!E8,Thursday!E8,Friday!E8,Saturday!E8,Sunday!E8) -> 0 | F67: =SUM(Monday!F8,Tuesday!F8,Wednesday!F8,Thursday!F8,Friday!F8,Saturday!F8,Sunday!F8) -> 0 | G67: =SUM(Monday!G8,Tuesday!G8,Wednesday!G8,Thursday!G8,Friday!G8,Saturday!G8,Sunday!G8) -> 0 | H67: =SUM(Monday!H8,Tuesday!H8,Wednesday!H8,Thursday!H8,Friday!H8,Saturday!H8,Sunday!H8) -> 0 | I67: =SUM(Monday!I8,Tuesday!I8,Wednesday!I8,Thursday!I8,Friday!I8,Saturday!I8,Sunday!I8) -> 0 | ... Z67: =SUM(Monday!Z8,Tuesday!Z8,Wednesday!Z8,Thursday!Z8,Friday!Z8,Saturday!Z8,Sunday!Z8) -> 0
A68: 6 | B68: =SUM(Monday!B9,Tuesday!B9,Wednesday!B9,Thursday!B9,Friday!B9,Saturday!B9,Sunday!B9) -> 0 | C68: =SUM(Monday!C9,Tuesday!C9,Wednesday!C9,Thursday!C9,Friday!C9,Saturday!C9,Sunday!C9) -> 0 | D68: =SUM(Monday!D9,Tuesday!D9,Wednesday!D9,Thursday!D9,Friday!D9,Saturday!D9,Sunday!D9) -> 0 | E68: =SUM(Monday!E9,Tuesday!E9,Wednesday!E9,Thursday!E9,Friday!E9,Saturday!E9,Sunday!E9) -> 0 | F68: =SUM(Monday!F9,Tuesday!F9,Wednesday!F9,Thursday!F9,Friday!F9,Saturday!F9,Sunday!F9) -> 0 | G68: =SUM(Monday!G9,Tuesday!G9,Wednesday!G9,Thursday!G9,Friday!G9,Saturday!G9,Sunday!G9) -> 0 | H68: =SUM(Monday!H9,Tuesday!H9,Wednesday!H9,Thursday!H9,Friday!H9,Saturday!H9,Sunday!H9) -> 0 | I68: =SUM(Monday!I9,Tuesday!I9,Wednesday!I9,Thursday!I9,Friday!I9,Saturday!I9,Sunday!I9) -> 0 | ... Z68: =SUM(Monday!Z9,Tuesday!Z9,Wednesday!Z9,Thursday!Z9,Friday!Z9,Saturday!Z9,Sunday!Z9) -> 0
A69: 7 | B69: =SUM(Monday!B10,Tuesday!B10,Wednesday!B10,Thursday!B10,Friday!B10,Saturday!B10,Sunday!B10) -> 0 | C69: =SUM(Monday!C10,Tuesday!C10,Wednesday!C10,Thursday!C10,Friday!C10,Saturday!C10,Sunday!C10) -> 0 | D69: =SUM(Monday!D10,Tuesday!D10,Wednesday!D10,Thursday!D10,Friday!D10,Saturday!D10,Sunday!D10) -> 0 | E69: =SUM(Monday!E10,Tuesday!E10,Wednesday!E10,Thursday!E10,Friday!E10,Saturday!E10,Sunday!E10) -> 0 | F69: =SUM(Monday!F10,Tuesday!F10,Wednesday!F10,Thursday!F10,Friday!F10,Saturday!F10,Sunday!F10) -> 0 | G69: =SUM(Monday!G10,Tuesday!G10,Wednesday!G10,Thursday!G10,Friday!G10,Saturday!G10,Sunday!G10) -> 0 | H69: =SUM(Monday!H10,Tuesday!H10,Wednesday!H10,Thursday!H10,Friday!H10,Saturday!H10,Sunday!H10) -> 0 | I69: =SUM(Monday!I10,Tuesday!I10,Wednesday!I10,Thursday!I10,Friday!I10,Saturday!I10,Sunday!I10) -> 0 | ... Z69: =SUM(Monday!Z10,Tuesday!Z10,Wednesday!Z10,Thursday!Z10,Friday!Z10,Saturday!Z10,Sunday!Z10) -> 0
A70: 8 | B70: =SUM(Monday!B11,Tuesday!B11,Wednesday!B11,Thursday!B11,Friday!B11,Saturday!B11,Sunday!B11) -> 0 | C70: =SUM(Monday!C11,Tuesday!C11,Wednesday!C11,Thursday!C11,Friday!C11,Saturday!C11,Sunday!C11) -> 0 | D70: =SUM(Monday!D11,Tuesday!D11,Wednesday!D11,Thursday!D11,Friday!D11,Saturday!D11,Sunday!D11) -> 0 | E70: =SUM(Monday!E11,Tuesday!E11,Wednesday!E11,Thursday!E11,Friday!E11,Saturday!E11,Sunday!E11) -> 0 | F70: =SUM(Monday!F11,Tuesday!F11,Wednesday!F11,Thursday!F11,Friday!F11,Saturday!F11,Sunday!F11) -> 0 | G70: =SUM(Monday!G11,Tuesday!G11,Wednesday!G11,Thursday!G11,Friday!G11,Saturday!G11,Sunday!G11) -> 0 | H70: =SUM(Monday!H11,Tuesday!H11,Wednesday!H11,Thursday!H11,Friday!H11,Saturday!H11,Sunday!H11) -> 0 | I70: =SUM(Monday!I11,Tuesday!I11,Wednesday!I11,Thursday!I11,Friday!I11,Saturday!I11,Sunday!I11) -> 0 | ... Z70: =SUM(Monday!Z11,Tuesday!Z11,Wednesday!Z11,Thursday!Z11,Friday!Z11,Saturday!Z11,Sunday!Z11) -> 0
A71: 9 | B71: =SUM(Monday!B12,Tuesday!B12,Wednesday!B12,Thursday!B12,Friday!B12,Saturday!B12,Sunday!B12) -> 0 | C71: =SUM(Monday!C12,Tuesday!C12,Wednesday!C12,Thursday!C12,Friday!C12,Saturday!C12,Sunday!C12) -> 0 | D71: =SUM(Monday!D12,Tuesday!D12,Wednesday!D12,Thursday!D12,Friday!D12,Saturday!D12,Sunday!D12) -> 0 | E71: =SUM(Monday!E12,Tuesday!E12,Wednesday!E12,Thursday!E12,Friday!E12,Saturday!E12,Sunday!E12) -> 0 | F71: =SUM(Monday!F12,Tuesday!F12,Wednesday!F12,Thursday!F12,Friday!F12,Saturday!F12,Sunday!F12) -> 0 | G71: =SUM(Monday!G12,Tuesday!G12,Wednesday!G12,Thursday!G12,Friday!G12,Saturday!G12,Sunday!G12) -> 0 | H71: =SUM(Monday!H12,Tuesday!H12,Wednesday!H12,Thursday!H12,Friday!H12,Saturday!H12,Sunday!H12) -> 0 | I71: =SUM(Monday!I12,Tuesday!I12,Wednesday!I12,Thursday!I12,Friday!I12,Saturday!I12,Sunday!I12) -> 0 | ... Z71: =SUM(Monday!Z12,Tuesday!Z12,Wednesday!Z12,Thursday!Z12,Friday!Z12,Saturday!Z12,Sunday!Z12) -> 0
A72: 10 | B72: =SUM(Monday!B13,Tuesday!B13,Wednesday!B13,Thursday!B13,Friday!B13,Saturday!B13,Sunday!B13) -> 0 | C72: =SUM(Monday!C13,Tuesday!C13,Wednesday!C13,Thursday!C13,Friday!C13,Saturday!C13,Sunday!C13) -> 0 | D72: =SUM(Monday!D13,Tuesday!D13,Wednesday!D13,Thursday!D13,Friday!D13,Saturday!D13,Sunday!D13) -> 0 | E72: =SUM(Monday!E13,Tuesday!E13,Wednesday!E13,Thursday!E13,Friday!E13,Saturday!E13,Sunday!E13) -> 0 | F72: =SUM(Monday!F13,Tuesday!F13,Wednesday!F13,Thursday!F13,Friday!F13,Saturday!F13,Sunday!F13) -> 0 | G72: =SUM(Monday!G13,Tuesday!G13,Wednesday!G13,Thursday!G13,Friday!G13,Saturday!G13,Sunday!G13) -> 0 | H72: =SUM(Monday!H13,Tuesday!H13,Wednesday!H13,Thursday!H13,Friday!H13,Saturday!H13,Sunday!H13) -> 0 | I72: =SUM(Monday!I13,Tuesday!I13,Wednesday!I13,Thursday!I13,Friday!I13,Saturday!I13,Sunday!I13) -> 0 | ... Z72: =SUM(Monday!Z13,Tuesday!Z13,Wednesday!Z13,Thursday!Z13,Friday!Z13,Saturday!Z13,Sunday!Z13) -> 0
A73: 11 | B73: =SUM(Monday!B14,Tuesday!B14,Wednesday!B14,Thursday!B14,Friday!B14,Saturday!B14,Sunday!B14) -> 0 | C73: =SUM(Monday!C14,Tuesday!C14,Wednesday!C14,Thursday!C14,Friday!C14,Saturday!C14,Sunday!C14) -> 0 | D73: =SUM(Monday!D14,Tuesday!D14,Wednesday!D14,Thursday!D14,Friday!D14,Saturday!D14,Sunday!D14) -> 0 | E73: =SUM(Monday!E14,Tuesday!E14,Wednesday!E14,Thursday!E14,Friday!E14,Saturday!E14,Sunday!E14) -> 0 | F73: =SUM(Monday!F14,Tuesday!F14,Wednesday!F14,Thursday!F14,Friday!F14,Saturday!F14,Sunday!F14) -> 0 | G73: =SUM(Monday!G14,Tuesday!G14,Wednesday!G14,Thursday!G14,Friday!G14,Saturday!G14,Sunday!G14) -> 0 | H73: =SUM(Monday!H14,Tuesday!H14,Wednesday!H14,Thursday!H14,Friday!H14,Saturday!H14,Sunday!H14) -> 0 | I73: =SUM(Monday!I14,Tuesday!I14,Wednesday!I14,Thursday!I14,Friday!I14,Saturday!I14,Sunday!I14) -> 0 | ... Z73: =SUM(Monday!Z14,Tuesday!Z14,Wednesday!Z14,Thursday!Z14,Friday!Z14,Saturday!Z14,Sunday!Z14) -> 0
A74: 12 | B74: =SUM(Monday!B15,Tuesday!B15,Wednesday!B15,Thursday!B15,Friday!B15,Saturday!B15,Sunday!B15) -> 0 | C74: =SUM(Monday!C15,Tuesday!C15,Wednesday!C15,Thursday!C15,Friday!C15,Saturday!C15,Sunday!C15) -> 0 | D74: =SUM(Monday!D15,Tuesday!D15,Wednesday!D15,Thursday!D15,Friday!D15,Saturday!D15,Sunday!D15) -> 0 | E74: =SUM(Monday!E15,Tuesday!E15,Wednesday!E15,Thursday!E15,Friday!E15,Saturday!E15,Sunday!E15) -> 0 | F74: =SUM(Monday!F15,Tuesday!F15,Wednesday!F15,Thursday!F15,Friday!F15,Saturday!F15,Sunday!F15) -> 0 | G74: =SUM(Monday!G15,Tuesday!G15,Wednesday!G15,Thursday!G15,Friday!G15,Saturday!G15,Sunday!G15) -> 0 | H74: =SUM(Monday!H15,Tuesday!H15,Wednesday!H15,Thursday!H15,Friday!H15,Saturday!H15,Sunday!H15) -> 0 | I74: =SUM(Monday!I15,Tuesday!I15,Wednesday!I15,Thursday!I15,Friday!I15,Saturday!I15,Sunday!I15) -> 0 | ... Z74: =SUM(Monday!Z15,Tuesday!Z15,Wednesday!Z15,Thursday!Z15,Friday!Z15,Saturday!Z15,Sunday!Z15) -> 0
... A118: 56 | B118: =SUM(Monday!B59,Tuesday!B59,Wednesday!B59,Thursday!B59,Friday!B59,Saturday!B59,Sunday!B59) -> 0 | C118: =SUM(Monday!C59,Tuesday!C59,Wednesday!C59,Thursday!C59,Friday!C59,Saturday!C59,Sunday!C59) -> 0 | D118: =SUM(Monday!D59,Tuesday!D59,Wednesday!D59,Thursday!D59,Friday!D59,Saturday!D59,Sunday!D59) -> 0 | E118: =SUM(Monday!E59,Tuesday!E59,Wednesday!E59,Thursday!E59,Friday!E59,Saturday!E59,Sunday!E59) -> 0 | F118: =SUM(Monday!F59,Tuesday!F59,Wednesday!F59,Thursday!F59,Friday!F59,Saturday!F59,Sunday!F59) -> 0 | G118: =SUM(Monday!G59,Tuesday!G59,Wednesday!G59,Thursday!G59,Friday!G59,Saturday!G59,Sunday!G59) -> 0 | H118: =SUM(Monday!H59,Tuesday!H59,Wednesday!H59,Thursday!H59,Friday!H59,Saturday!H59,Sunday!H59) -> 0 | I118: =SUM(Monday!I59,Tuesday!I59,Wednesday!I59,Thursday!I59,Friday!I59,Saturday!I59,Sunday!I59) -> 0 | ... Z118: =SUM(Monday!Z59,Tuesday!Z59,Wednesday!Z59,Thursday!Z59,Friday!Z59,Saturday!Z59,Sunday!Z59) -> 0

Sheet Daily
A1: Monday
A2: Lane | B2: 180 | C2: Blackout | D2: Ball Return | E2: Respot | F2: Other | G2: Daily Total | I2: Daily Combined Total: | J2: =SUM(G3:G58) -> 0
A3: 1 | B3: =SUM(Monday!B4:Monday!H4) -> 0 | C3: =SUM(Monday!I4:Monday!L4) -> 0 | D3: =SUM(Monday!M4:Monday!X4) -> 0 | E3: =SUM(Monday!Y4) -> 0 | F3: =SUM(Monday!Z4) -> 0 | G3: =SUM(B3:F3) -> 0 | I3: Daily Games:
A4: 2 | B4: =SUM(Monday!B5:Monday!H5) -> 0 | C4: =SUM(Monday!I5:Monday!L5) -> 0 | D4: =SUM(Monday!M5:Monday!X5) -> 0 | E4: =SUM(Monday!Y5) -> 0 | F4: =SUM(Monday!Z5) -> 0 | G4: =SUM(B4:F4) -> 0 | I4: Daily FPS: | J4: =(J3*10)/J2 -> #DIV/0!
A5: 3 | B5: =SUM(Monday!B6:Monday!H6) -> 0 | C5: =SUM(Monday!I6:Monday!L6) -> 0 | D5: =SUM(Monday!M6:Monday!X6) -> 0 | E5: =SUM(Monday!Y6) -> 0 | F5: =SUM(Monday!Z6) -> 0 | G5: =SUM(B5:F5) -> 0
A6: 4 | B6: =SUM(Monday!B7:Monday!H7) -> 0 | C6: =SUM(Monday!I7:Monday!L7) -> 0 | D6: =SUM(Monday!M7:Monday!X7) -> 0 | E6: =SUM(Monday!Y7) -> 0 | F6: =SUM(Monday!Z7) -> 0 | G6: =SUM(B6:F6) -> 0
A7: 5 | B7: =SUM(Monday!B8:Monday!H8) -> 0 | C7: =SUM(Monday!I8:Monday!L8) -> 0 | D7: =SUM(Monday!M8:Monday!X8) -> 0 | E7: =SUM(Monday!Y8) -> 0 | F7: =SUM(Monday!Z8) -> 0 | G7: =SUM(B7:F7) -> 0
A8: 6 | B8: =SUM(Monday!B9:Monday!H9) -> 0 | C8: =SUM(Monday!I9:Monday!L9) -> 0 | D8: =SUM(Monday!M9:Monday!X9) -> 0 | E8: =SUM(Monday!Y9) -> 0 | F8: =SUM(Monday!Z9) -> 0 | G8: =SUM(B8:F8) -> 0
A9: 7 | B9: =SUM(Monday!B10:Monday!H10) -> 0 | C9: =SUM(Monday!I10:Monday!L10) -> 0 | D9: =SUM(Monday!M10:Monday!X10) -> 0 | E9: =SUM(Monday!Y10) -> 0 | F9: =SUM(Monday!Z10) -> 0 | G9: =SUM(B9:F9) -> 0
A10: 8 | B10: =SUM(Monday!B11:Monday!H11) -> 0 | C10: =SUM(Monday!I11:Monday!L11) -> 0 | D10: =SUM(Monday!M11:Monday!X11) -> 0 | E10: =SUM(Monday!Y11) -> 0 | F10: =SUM(Monday!Z11) -> 0 | G10: =SUM(B10:F10) -> 0
A11: 9 | B11: =SUM(Monday!B12:Monday!H12) -> 0 | C11: =SUM(Monday!I12:Monday!L12) -> 0 | D11: =SUM(Monday!M12:Monday!X12) -> 0 | E11: =SUM(Monday!Y12) -> 0 | F11: =SUM(Monday!Z12) -> 0 | G11: =SUM(B11:F11) -> 0
A12: 10 | B12: =SUM(Monday!B13:Monday!H13) -> 0 | C12: =SUM(Monday!I13:Monday!L13) -> 0 | D12: =SUM(Monday!M13:Monday!X13) -> 0 | E12: =SUM(Monday!Y13) -> 0 | F12: =SUM(Monday!Z13) -> 0 | G12: =SUM(B12:F12) -> 0
A13: 11 | B13: =SUM(Monday!B14:Monday!H14) -> 0 | C13: =SUM(Monday!I14:Monday!L14) -> 0 | D13: =SUM(Monday!M14:Monday!X14) -> 0 | E13: =SUM(Monday!Y14) -> 0 | F13: =SUM(Monday!Z14) -> 0 | G13: =SUM(B13:F13) -> 0
A14: 12 | B14: =SUM(Monday!B15:Monday!H15) -> 0 | C14: =SUM(Monday!I15:Monday!L15) -> 0 | D14: =SUM(Monday!M15:Monday!X15) -> 0 | E14: =SUM(Monday!Y15) -> 0 | F14: =SUM(Monday!Z15) -> 0 | G14: =SUM(B14:F14) -> 0
A15: 13 | B15: =SUM(Monday!B16:Monday!H16) -> 0 | C15: =SUM(Monday!I16:Monday!L16) -> 0 | D15: =SUM(Monday!M16:Monday!X16) -> 0 | E15: =SUM(Monday!Y16) -> 0 | F15: =SUM(Monday!Z16) -> 0 | G15: =SUM(B15:F15) -> 0
A16: 14 | B16: =SUM(Monday!B17:Monday!H17) -> 0 | C16: =SUM(Monday!I17:Monday!L17) -> 0 | D16: =SUM(Monday!M17:Monday!X17) -> 0 | E16: =SUM(Monday!Y17) -> 0 | F16: =SUM(Monday!Z17) -> 0 | G16: =SUM(B16:F16) -> 0
... A58: 56 | B58: =SUM(Monday!B59:Monday!H59) -> 0 | C58: =SUM(Monday!I59:Monday!L59) -> 0 | D58: =SUM(Monday!M59:Monday!X59) -> 0 | E58: =SUM(Monday!Y59) -> 0 | F58: =SUM(Monday!Z59) -> 0 | G58: =SUM(B58:F58) -> 0
A60: Tuesday
A61: Lane | B61: 180 | C61: Blackout | D61: Ball Return | E61: Respot | F61: Other | G61: Daily Total | I61: Daily Combined Total: | J61: =SUM(G62:G117) -> 0
A62: 1 | B62: =SUM(Tuesday!B4:Tuesday!H4) -> 0 | C62: =SUM(Tuesday!I4:Tuesday!L4) -> 0 | D62: =SUM(Tuesday!M4:Tuesday!X4) -> 0 | E62: =SUM(Tuesday!Y4) -> 0 | F62: =SUM(Tuesday!Z4) -> 0 | G62: =SUM(B62:F62) -> 0 | I62: Daily Games:
A63: 2 | B63: =SUM(Tuesday!B5:Tuesday!H5) -> 0 | C63: =SUM(Tuesday!I5:Tuesday!L5) -> 0 | D63: =SUM(Tuesday!M5:Tuesday!X5) -> 0 | E63: =SUM(Tuesday!Y5) -> 0 | F63: =SUM(Tuesday!Z5) -> 0 | G63: =SUM(B63:F63) -> 0 | I63: Daily FPS: | J63: =(J62*10)/J61 -> #DIV/0!
A64: 3 | B64: =SUM(Tuesday!B6:Tuesday!H6) -> 0 | C64: =SUM(Tuesday!I6:Tuesday!L6) -> 0 | D64: =SUM(Tuesday!M6:Tuesday!X6) -> 0 | E64: =SUM(Tuesday!Y6) -> 0 | F64: =SUM(Tuesday!Z6) -> 0 | G64: =SUM(B64:F64) -> 0
A65: 4 | B65: =SUM(Tuesday!B7:Tuesday!H7) -> 0 | C65: =SUM(Tuesday!I7:Tuesday!L7) -> 0 | D65: =SUM(Tuesday!M7:Tuesday!X7) -> 0 | E65: =SUM(Tuesday!Y7) -> 0 | F65: =SUM(Tuesday!Z7) -> 0 | G65: =SUM(B65:F65) -> 0
A66: 5 | B66: =SUM(Tuesday!B8:Tuesday!H8) -> 0 | C66: =SUM(Tuesday!I8:Tuesday!L8) -> 0 | D66: =SUM(Tuesday!M8:Tuesday!X8) -> 0 | E66: =SUM(Tuesday!Y8) -> 0 | F66: =SUM(Tuesday!Z8) -> 0 | G66: =SUM(B66:F66) -> 0
A67: 6 | B67: =SUM(Tuesday!B9:Tuesday!H9) -> 0 | C67: =SUM(Tuesday!I9:Tuesday!L9) -> 0 | D67: =SUM(Tuesday!M9:Tuesday!X9) -> 0 | E67: =SUM(Tuesday!Y9) -> 0 | F67: =SUM(Tuesday!Z9) -> 0 | G67: =SUM(B67:F67) -> 0
A68: 7 | B68: =SUM(Tuesday!B10:Tuesday!H10) -> 0 | C68: =SUM(Tuesday!I10:Tuesday!L10) -> 0 | D68: =SUM(Tuesday!M10:Tuesday!X10) -> 0 | E68: =SUM(Tuesday!Y10) -> 0 | F68: =SUM(Tuesday!Z10) -> 0 | G68: =SUM(B68:F68) -> 0
A69: 8 | B69: =SUM(Tuesday!B11:Tuesday!H11) -> 0 | C69: =SUM(Tuesday!I11:Tuesday!L11) -> 0 | D69: =SUM(Tuesday!M11:Tuesday!X11) -> 0 | E69: =SUM(Tuesday!Y11) -> 0 | F69: =SUM(Tuesday!Z11) -> 0 | G69: =SUM(B69:F69) -> 0
A70: 9 | B70: =SUM(Tuesday!B12:Tuesday!H12) -> 0 | C70: =SUM(Tuesday!I12:Tuesday!L12) -> 0 | D70: =SUM(Tuesday!M12:Tuesday!X12) -> 0 | E70: =SUM(Tuesday!Y12) -> 0 | F70: =SUM(Tuesday!Z12) -> 0 | G70: =SUM(B70:F70) -> 0
A71: 10 | B71: =SUM(Tuesday!B13:Tuesday!H13) -> 0 | C71: =SUM(Tuesday!I13:Tuesday!L13) -> 0 | D71: =SUM(Tuesday!M13:Tuesday!X13) -> 0 | E71: =SUM(Tuesday!Y13) -> 0 | F71: =SUM(Tuesday!Z13) -> 0 | G71: =SUM(B71:F71) -> 0
A72: 11 | B72: =SUM(Tuesday!B14:Tuesday!H14) -> 0 | C72: =SUM(Tuesday!I14:Tuesday!L14) -> 0 | D72: =SUM(Tuesday!M14:Tuesday!X14) -> 0 | E72: =SUM(Tuesday!Y14) -> 0 | F72: =SUM(Tuesday!Z14) -> 0 | G72: =SUM(B72:F72) -> 0
A73: 12 | B73: =SUM(Tuesday!B15:Tuesday!H15) -> 0 | C73: =SUM(Tuesday!I15:Tuesday!L15) -> 0 | D73: =SUM(Tuesday!M15:Tuesday!X15) -> 0 | E73: =SUM(Tuesday!Y15) -> 0 | F73: =SUM(Tuesday!Z15) -> 0 | G73: =SUM(B73:F73) -> 0
A74: 13 | B74: =SUM(Tuesday!B16:Tuesday!H16) -> 0 | C74: =SUM(Tuesday!I16:Tuesday!L16) -> 0 | D74: =SUM(Tuesday!M16:Tuesday!X16) -> 0 | E74: =SUM(Tuesday!Y16) -> 0 | F74: =SUM(Tuesday!Z16) -> 0 | G74: =SUM(B74:F74) -> 0
A75: 14 | B75: =SUM(Tuesday!B17:Tuesday!H17) -> 0 | C75: =SUM(Tuesday!I17:Tuesday!L17) -> 0 | D75: =SUM(Tuesday!M17:Tuesday!X17) -> 0 | E75: =SUM(Tuesday!Y17) -> 0 | F75: =SUM(Tuesday!Z17) -> 0 | G75: =SUM(B75:F75) -> 0
... A117: 56 | B117: =SUM(Tuesday!B59:Tuesday!H59) -> 0 | C117: =SUM(Tuesday!I59:Tuesday!L59) -> 0 | D117: =SUM(Tuesday!M59:Tuesday!X59) -> 0 | E117: =SUM(Tuesday!Y59) -> 0 | F117: =SUM(Tuesday!Z59) -> 0 | G117: =SUM(B117:F117) -> 0
A119: Wednesday
A120: Lane | B120: 180 | C120: Blackout | D120: Ball Return | E120: Respot | F120: Other | G120: Daily Total | I120: Daily Combined Total: | J120: =SUM(G121:G176) -> 0
A121: 1 | B121: =SUM(Wednesday!B4:Wednesday!H4) -> 0 | C121: =SUM(Wednesday!I4:Wednesday!L4) -> 0 | D121: =SUM(Wednesday!M4:Wednesday!X4) -> 0 | E121: =SUM(Wednesday!Y4) -> 0 | F121: =SUM(Wednesday!Z4) -> 0 | G121: =SUM(B121:F121) -> 0 | I121: Daily Games:
A122: 2 | B122: =SUM(Wednesday!B5:Wednesday!H5) -> 0 | C122: =SUM(Wednesday!I5:Wednesday!L5) -> 0 | D122: =SUM(Wednesday!M5:Wednesday!X5) -> 0 | E122: =SUM(Wednesday!Y5) -> 0 | F122: =SUM(Wednesday!Z5) -> 0 | G122: =SUM(B122:F122) -> 0 | I122: Daily FPS: | J122: =(J121*10)/J120 -> #DIV/0!
A123: 3 | B123: =SUM(Wednesday!B6:Wednesday!H6) -> 0 | C123: =SUM(Wednesday!I6:Wednesday!L6) -> 0 | D123: =SUM(Wednesday!M6:Wednesday!X6) -> 0 | E123: =SUM(Wednesday!Y6) -> 0 | F123: =SUM(Wednesday!Z6) -> 0 | G123: =SUM(B123:F123) -> 0
A124: 4 | B124: =SUM(Wednesday!B7:Wednesday!H7) -> 0 | C124: =SUM(Wednesday!I7:Wednesday!L7) -> 0 | D124: =SUM(Wednesday!M7:Wednesday!X7) -> 0 | E124: =SUM(Wednesday!Y7) -> 0 | F124: =SUM(Wednesday!Z7) -> 0 | G124: =SUM(B124:F124) -> 0
...

Sheet Monday
A1: Monday
B2: 180 | I2: Black Out | M2: Ball Return | Y2: Other
A3: Lane | B3: Ball Blocking Pins | C3: Pin Guide Jam | D3: Turn Pan Jam | E3: Pin Gate Locked | F3: Pin Head First | G3: Turret Jam | H3: Other | I3: Deck Jam | J3: Turn Pan Jam | K3: Electrical | L3: Other | M3: Pins Blocking Ball | N3: Spinning | O3: Under Elbow | P3: In Pin Wheel | Q3: Between Lift Rod & Pit Cushion | R3: Yo-Yo | S3: Top Of Lift Rod | T3: Locked @ Pref | U3: Pin in Return Track | V3: @Y | W3: In Front of Pit Cushion | X3: Other | Y3: Respot | Z3: Other
A4: 1 | B4: 0 | C4: 0 | D4: 0 | E4: 0 | F4: 0 | G4: 0 | H4: 0 | I4: 0 | J4: 0 | K4: 0 | L4: 0 | M4: 0 | N4: 0 | O4: 0 | P4: 0 | Q4: 0 | R4: 0 | S4: 0 | T4: 0 | U4: 0 | V4: 0 | W4: 0 | X4: 0 | Y4: 0 | Z4: 0
A5: 2 | B5: 0 | C5: 0 | D5: 0 | E5: 0 | F5: 0 | G5: 0 | H5: 0 | I5: 0 | J5: 0 | K5: 0 | L5: 0 | M5: 0 | N5: 0 | O5: 0 | P5: 0 | Q5: 0 | R5: 0 | S5: 0 | T5: 0 | U5: 0 | V5: 0 | W5: 0 | X5: 0 | Y5: 0 | Z5: 0
A6: 3 | B6: 0 | C6: 0 | D6: 0 | E6: 0 | F6: 0 | G6: 0 | H6: 0 | I6: 0 | J6: 0 | K6: 0 | L6: 0 | M6: 0 | N6: 0 | O6: 0 | P6: 0 | Q6: 0 | R6: 0 | S6: 0 | T6: 0 | U6: 0 | V6: 0 | W6: 0 | X6: 0 | Y6: 0 | Z6: 0
A7: 4 | B7: 0 | C7: 0 | D7: 0 | E7: 0 | F7: 0 | G7: 0 | H7: 0 | I7: 0 | J7: 0 | K7: 0 | L7: 0 | M7: 0 | N7: 0 | O7: 0 | P7: 0 | Q7: 0 | R7: 0 | S7: 0 | T7: 0 | U7: 0 | V7: 0 | W7: 0 | X7: 0 | Y7: 0 | Z7: 0
A8: 5 | B8: 0 | C8: 0 | D8: 0 | E8: 0 | F8: 0 | G8: 0 | H8: 0 | I8: 0 | J8: 0 | K8: 0 | L8: 0 | M8: 0 | N8: 0 | O8: 0 | P8: 0 | Q8: 0 | R8: 0 | S8: 0 | T8: 0 | U8: 0 | V8: 0 | W8: 0 | X8: 0 | Y8: 0 | Z8: 0
A9: 6 | B9: 0 | C9: 0 | D9: 0 | E9: 0 | F9: 0 | G9: 0 | H9: 0 | I9: 0 | J9: 0 | K9: 0 | L9: 0 | M9: 0 | N9: 0 | O9: 0 | P9: 0 | Q9: 0 | R9: 0 | S9: 0 | T9: 0 | U9: 0 | V9: 0 | W9: 0 | X9: 0 | Y9: 0 | Z9: 0
A10: 7 | B10: 0 | C10: 0 | D10: 0 | E10: 0 | F10: 0 | G10: 0 | H10: 0 | I10: 0 | J10: 0 | K10: 0 | L10: 0 | M10: 0 | N10: 0 | O10: 0 | P10: 0 | Q10: 0 | R10: 0 | S10: 0 | T10: 0 | U10: 0 | V10: 0 | W10: 0 | X10: 0 | Y10: 0 | Z10: 0
A11: 8 | B11: 0 | C11: 0 | D11: 0 | E11: 0 | F11: 0 | G11: 0 | H11: 0 | I11: 0 | J11: 0 | K11: 0 | L11: 0 | M11: 0 | N11: 0 | O11: 0 | P11: 0 | Q11: 0 | R11: 0 | S11: 0 | T11: 0 | U11: 0 | V11: 0 | W11: 0 | X11: 0 | Y11: 0 | Z11: 0
A12: 9 | B12: 0 | C12: 0 | D12: 0 | E12: 0 | F12: 0 | G12: 0 | H12: 0 | I12: 0 | J12: 0 | K12: 0 | L12: 0 | M12: 0 | N12: 0 | O12: 0 | P12: 0 | Q12: 0 | R12: 0 | S12: 0 | T12: 0 | U12: 0 | V12: 0 | W12: 0 | X12: 0 | Y12: 0 | Z12: 0
A13: 10 | B13: 0 | C13: 0 | D13: 0 | E13: 0 | F13: 0 | G13: 0 | H13: 0 | I13: 0 | J13: 0 | K13: 0 | L13: 0 | M13: 0 | N13: 0 | O13: 0 | P13: 0 | Q13: 0 | R13: 0 | S13: 0 | T13: 0 | U13: 0 | V13: 0 | W13: 0 | X13: 0 | Y13: 0 | Z13: 0
A14: 11 | B14: 0 | C14: 0 | D14: 0 | E14: 0 | F14: 0 | G14: 0 | H14: 0 | I14: 0 | J14: 0 | K14: 0 | L14: 0 | M14: 0 | N14: 0 | O14: 0 | P14: 0 | Q14: 0 | R14: 0 | S14: 0 | T14: 0 | U14: 0 | V14: 0 | W14: 0 | X14: 0 | Y14: 0 | Z14: 0
A15: 12 | B15: 0 | C15: 0 | D15: 0 | E15: 0 | F15: 0 | G15: 0 | H15: 0 | I15: 0 | J15: 0 | K15: 0 | L15: 0 | M15: 0 | N15: 0 | O15: 0 | P15: 0 | Q15: 0 | R15: 0 | S15: 0 | T15: 0 | U15: 0 | V15: 0 | W15: 0 | X15: 0 | Y15: 0 | Z15: 0
... A59: 56 | B59: 0 | C59: 0 | D59: 0 | E59: 0 | F59: 0 | G59: 0 | H59: 0 | I59: 0 | J59: 0 | K59: 0 | L59: 0 | M59: 0 | N59: 0 | O59: 0 | P59: 0 | Q59: 0 | R59: 0 | S59: 0 | T59: 0 | U59: 0 | V59: 0 | W59: 0 | X59: 0 | Y59: 0 | Z59: 0

Sheet Tuesday
A1: Tuesday
B2: 180 | I2: Black Out | M2: Ball Return | Y2: Other
A3: Lane | B3: Ball Blocking Pins | C3: Pin Guide Jam | D3: Turn Pan Jam | E3: Pin Gate Locked | F3: Pin Head First | G3: Turret Jam | H3: Other | I3: Deck Jam | J3: Turn Pan Jam | K3: Electrical | L3: Other | M3: Pins Blocking Ball | N3: Spinning | O3: Under Elbow | P3: In Pin Wheel | Q3: Between Lift Rod & Pit Cushion | R3: Yo-Yo | S3: Top Of Lift Rod | T3: Locked @ Pref | U3: Pin in Return Track | V3: @Y | W3: In Front of Pit Cushion | X3: Other | Y3: Respot | Z3: Other
A4: 1 | B4: 0 | C4: 0 | D4: 0 | E4: 0 | F4: 0 | G4: 0 | H4: 0 | I4: 0 | J4: 0 | K4: 0 | L4: 0 | M4: 0 | N4: 0 | O4: 0 | P4: 0 | Q4: 0 | R4: 0 | S4: 0 | T4: 0 | U4: 0 | V4: 0 | W4: 0 | X4: 0 | Y4: 0 | Z4: 0
A5: 2 | B5: 0 | C5: 0 | D5: 0 | E5: 0 | F5: 0 | G5: 0 | H5: 0 | I5: 0 | J5: 0 | K5: 0 | L5: 0 | M5: 0 | N5: 0 | O5: 0 | P5: 0 | Q5: 0 | R5: 0 | S5: 0 | T5: 0 | U5: 0 | V5: 0 | W5: 0 | X5: 0 | Y5: 0 | Z5: 0
A6: 3 | B6: 0 | C6: 0 | D6: 0 | E6: 0 | F6: 0 | G6: 0 | H6: 0 | I6: 0 | J6: 0 | K6: 0 | L6: 0 | M6: 0 | N6: 0 | O6: 0 | P6: 0 | Q6: 0 | R6: 0 | S6: 0 | T6: 0 | U6: 0 | V6: 0 | W6: 0 | X6: 0 | Y6: 0 | Z6: 0
A7: 4 | B7: 0 | C7: 0 | D7: 0 | E7: 0 | F7: 0 | G7: 0 | H7: 0 | I7: 0 | J7: 0 | K7: 0 | L7: 0 | M7: 0 | N7: 0 | O7: 0 | P7: 0 | Q7: 0 | R7: 0 | S7: 0 | T7: 0 | U7: 0 | V7: 0 | W7: 0 | X7: 0 | Y7: 0 | Z7: 0
A8: 5 | B8: 0 | C8: 0 | D8: 0 | E8: 0 | F8: 0 | G8: 0 | H8: 0 | I8: 0 | J8: 0 | K8: 0 | L8: 0 | M8: 0 | N8: 0 | O8: 0 | P8: 0 | Q8: 0 | R8: 0 | S8: 0 | T8: 0 | U8: 0 | V8: 0 | W8: 0 | X8: 0 | Y8: 0 | Z8: 0
A9: 6 | B9: 0 | C9: 0 | D9: 0 | E9: 0 | F9: 0 | G9: 0 | H9: 0 | I9: 0 | J9: 0 | K9: 0 | L9: 0 | M9: 0 | N9: 0 | O9: 0 | P9: 0 | Q9: 0 | R9: 0 | S9: 0 | T9: 0 | U9: 0 | V9: 0 | W9: 0 | X9: 0 | Y9: 0 | Z9: 0
A10: 7 | B10: 0 | C10: 0 | D10: 0 | E10: 0 | F10: 0 | G10: 0 | H10: 0 | I10: 0 | J10: 0 | K10: 0 | L10: 0 | M10: 0 | N10: 0 | O10: 0 | P10: 0 | Q10: 0 | R10: 0 | S10: 0 | T10: 0 | U10: 0 | V10: 0 | W10: 0 | X10: 0 | Y10: 0 | Z10: 0
A11: 8 | B11: 0 | C11: 0 | D11: 0 | E11: 0 | F11: 0 | G11: 0 | H11: 0 | I11: 0 | J11: 0 | K11: 0 | L11: 0 | M11: 0 | N11: 0 | O11: 0 | P11: 0 | Q11: 0 | R11: 0 | S11: 0 | T11: 0 | U11: 0 | V11: 0 | W11: 0 | X11: 0 | Y11: 0 | Z11: 0
A12: 9 | B12: 0 | C12: 0 | D12: 0 | E12: 0 | F12: 0 | G12: 0 | H12: 0 | I12: 0 | J12: 0 | K12: 0 | L12: 0 | M12: 0 | N12: 0 | O12: 0 | P12: 0 | Q12: 0 | R12: 0 | S12: 0 | T12: 0 | U12: 0 | V12: 0 | W12: 0 | X12: 0 | Y12: 0 | Z12: 0
A13: 10 | B13: 0 | C13: 0 | D13: 0 | E13: 0 | F13: 0 | G13: 0 | H13: 0 | I13: 0 | J13: 0 | K13: 0 | L13: 0 | M13: 0 | N13: 0 | O13: 0 | P13: 0 | Q13: 0 | R13: 0 | S13: 0 | T13: 0 | U13: 0 | V13: 0 | W13: 0 | X13: 0 | Y13: 0 | Z13: 0
A14: 11 | B14: 0 | C14: 0 | D14: 0 | E14: 0 | F14: 0 | G14: 0 | H14: 0 | I14: 0 | J14: 0 | K14: 0 | L14: 0 | M14: 0 | N14: 0 | O14: 0 | P14: 0 | Q14: 0 | R14: 0 | S14: 0 | T14: 0 | U14: 0 | V14: 0 | W14: 0 | X14: 0 | Y14: 0 | Z14: 0
A15: 12 | B15: 0 | C15: 0 | D15: 0 | E15: 0 | F15: 0 | G15: 0 | H15: 0 | I15: 0 | J15: 0 | K15: 0 | L15: 0 | M15: 0 | N15: 0 | O15: 0 | P15: 0 | Q15: 0 | R15: 0 | S15: 0 | T15: 0 | U15: 0 | V15: 0 | W15: 0 | X15: 0 | Y15: 0 | Z15: 0
... A59: 56 | B59: 0 | C59: 0 | D59: 0 | E59: 0 | F59: 0 | G59: 0 | H59: 0 | I59: 0 | J59: 0 | K59: 0 | L59: 0 | M59: 0 | N59: 0 | O59: 0 | P59: 0 | Q59: 0 | R59: 0 | S59: 0 | T59: 0 | U59: 0 | V59: 0 | W59: 0 | X59: 0 | Y59: 0 | Z59: 0

Sheet Wednesday
A1: Wednesday
B2: 180 | I2: Black Out | M2: Ball Return | Y2: Other
A3: Lane | B3: Ball Blocking Pins | C3: Pin Guide Jam | D3: Turn Pan Jam | E3: Pin Gate Locked | F3: Pin Head First | G3: Turret Jam | H3: Other | I3: Deck Jam | J3: Turn Pan Jam | K3: Electrical | L3: Other | M3: Pins Blocking Ball | N3: Spinning | O3: Under Elbow | P3: In Pin Wheel | Q3: Between Lift Rod & Pit Cushion | R3: Yo-Yo | S3: Top Of Lift Rod | T3: Locked @ Pref | U3: Pin in Return Track | V3: @Y | W3: In Front of Pit Cushion | X3: Other | Y3: Respot | Z3: Other
A4: 1 | B4: 0 | C4: 0 | D4: 0 | E4: 0 | F4: 0 | G4: 0 | H4: 0 | I4: 0 | J4: 0 | K4: 0 | L4: 0 | M4: 0 | N4: 0 | O4: 0 | P4: 0 | Q4: 0 | R4: 0 | S4: 0 | T4: 0 | U4: 0 | V4: 0 | W4: 0 | X4: 0 | Y4: 0 | Z4: 0
A5: 2 | B5: 0 | C5: 0 | D5: 0 | E5: 0 | F5: 0 | G5: 0 | H5: 0 | I5: 0 | J5: 0 | K5: 0 | L5: 0 | M5: 0 | N5: 0 | O5: 0 | P5: 0 | Q5: 0 | R5: 0 | S5: 0 | T5: 0 | U5: 0 | V5: 0 | W5: 0 | X5: 0 | Y5: 0 | Z5: 0
A6: 3 | B6: 0 | C6: 0 | D6: 0 | E6: 0 | F6: 0 | G6: 0 | H6: 0 | I6: 0 | J6: 0 | K6: 0 | L6: 0 | M6: 0 | N6: 0 | O6: 0 | P6: 0 | Q6: 0 | R6: 0 | S6: 0 | T6: 0 | U6: 0 | V6: 0 | W6: 0 | X6: 0 | Y6: 0 | Z6: 0
A7: 4 | B7: 0 | C7: 0 | D7: 0 | E7: 0 | F7: 0 | G7: 0 | H7: 0 | I7: 0 | J7: 0 | K7: 0 | L7: 0 | M7: 0 | N7: 0 | O7: 0 | P7: 0 | Q7: 0 | R7: 0 | S7: 0 | T7: 0 | U7: 0 | V7: 0 | W7: 0 | X7: 0 | Y7: 0 | Z7: 0
A8: 5 | B8: 0 | C8: 0 | D8: 0 | E8: 0 | F8: 0 | G8: 0 | H8: 0 | I8: 0 | J8: 0 | K8: 0 | L8: 0 | M8: 0 | N8: 0 | O8: 0 | P8: 0 | Q8: 0 | R8: 0 | S8: 0 | T8: 0 | U8: 0 | V8: 0 | W8: 0 | X8: 0 | Y8: 0 | Z8: 0
A9: 6 | B9: 0 | C9: 0 | D9: 0 | E9: 0 | F9: 0 | G9: 0 | H9: 0 | I9: 0 | J9: 0 | K9: 0 | L9: 0 | M9: 0 | N9: 0 | O9: 0 | P9: 0 | Q9: 0 | R9: 0 | S9: 0 | T9: 0 | U9: 0 | V9: 0 | W9: 0 | X9: 0 | Y9: 0 | Z9: 0
A10: 7 | B10: 0 | C10: 0 | D10: 0 | E10: 0 | F10: 0 | G10: 0 | H10: 0 | I10: 0 | J10: 0 | K10: 0 | L10: 0 | M10: 0 | N10: 0 | O10: 0 | P10: 0 | Q10: 0 | R10: 0 | S10: 0 | T10: 0 | U10: 0 | V10: 0 | W10: 0 | X10: 0 | Y10: 0 | Z10: 0
A11: 8 | B11: 0 | C11: 0 | D11: 0 | E11: 0 | F11: 0 | G11: 0 | H11: 0 | I11: 0 | J11: 0 | K11: 0 | L11: 0 | M11: 0 | N11: 0 | O11: 0 | P11: 0 | Q11: 0 | R11: 0 | S11: 0 | T11: 0 | U11: 0 | V11: 0 | W11: 0 | X11: 0 | Y11: 0 | Z11: 0
A12: 9 | B12: 0 | C12: 0 | D12: 0 | E12: 0 | F12: 0 | G12: 0 | H12: 0 | I12: 0 | J12: 0 | K12: 0 | L12: 0 | M12: 0 | N12: 0 | O12: 0 | P12: 0 | Q12: 0 | R12: 0 | S12: 0 | T12: 0 | U12: 0 | V12: 0 | W12: 0 | X12: 0 | Y12: 0 | Z12: 0
A13: 10 | B13: 0 | C13: 0 | D13: 0 | E13: 0 | F13: 0 | G13: 0 | H13: 0 | I13: 0 | J13: 0 | K13: 0 | L13: 0 | M13: 0 | N13: 0 | O13: 0 | P13: 0 | Q13: 0 | R13: 0 | S13: 0 | T13: 0 | U13: 0 | V13: 0 | W13: 0 | X13: 0 | Y13: 0 | Z13: 0
A14: 11 | B14: 0 | C14: 0 | D14: 0 | E14: 0 | F14: 0 | G14: 0 | H14: 0 | I14: 0 | J14: 0 | K14: 0 | L14: 0 | M14: 0 | N14: 0 | O14: 0 | P14: 0 | Q14: 0 | R14: 0 | S14: 0 | T14: 0 | U14: 0 | V14: 0 | W14: 0 | X14: 0 | Y14: 0 | Z14: 0
A15: 12 | B15: 0 | C15: 0 | D15: 0 | E15: 0 | F15: 0 | G15: 0 | H15: 0 | I15: 0 | J15: 0 | K15: 0 | L15: 0 | M15: 0 | N15: 0 | O15: 0 | P15: 0 | Q15: 0 | R15: 0 | S15: 0 | T15: 0 | U15: 0 | V15: 0 | W15: 0 | X15: 0 | Y15: 0 | Z15: 0
... A59: 56 | B59: 0 | C59: 0 | D59: 0 | E59: 0 | F59: 0 | G59: 0 | H59: 0 | I59: 0 | J59: 0 | K59: 0 | L59: 0 | M59: 0 | N59: 0 | O59: 0 | P59: 0 | Q59: 0 | R59: 0 | S59: 0 | T59: 0 | U59: 0 | V59: 0 | W59: 0 | X59: 0 | Y59: 0 | Z59: 0

Sheet Thursday
A1: Thursday
B2: 180 | I2: Black Out | M2: Ball Return | Y2: Other
A3: Lane | B3: Ball Blocking Pins | C3: Pin Guide Jam | D3: Turn Pan Jam | E3: Pin Gate Locked | F3: Pin Head First | G3: Turret Jam | H3: Other | I3: Deck Jam | J3: Turn Pan Jam | K3: Electrical | L3: Other | M3: Pins Blocking Ball | N3: Spinning | O3: Under Elbow | P3: In Pin Wheel | Q3: Between Lift Rod & Pit Cushion | R3: Yo-Yo | S3: Top Of Lift Rod | T3: Locked @ Pref | U3: Pin in Return Track | V3: @Y | W3: In Front of Pit Cushion | X3: Other | Y3: Respot | Z3: Other
A4: 1 | B4: 0 | C4: 0 | D4: 0 | E4: 0 | F4: 0 | G4: 0 | H4: 0 | I4: 0 | J4: 0 | K4: 0 | L4: 0 | M4: 0 | N4: 0 | O4: 0 | P4: 0 | Q4: 0 | R4: 0 | S4: 0 | T4: 0 | U4: 0 | V4: 0 | W4: 0 | X4: 0 | Y4: 0 | Z4: 0
A5: 2 | B5: 0 | C5: 0 | D5: 0 | E5: 0 | F5: 0 | G5: 0 | H5: 0 | I5: 0 | J5: 0 | K5: 0 | L5: 0 | M5: 0 | N5: 0 | O5: 0 | P5: 0 | Q5: 0 | R5: 0 | S5: 0 | T5: 0 | U5: 0 | V5: 0 | W5: 0 | X5: 0 | Y5: 0 | Z5: 0
A6: 3 | B6: 0 | C6: 0 | D6: 0 | E6: 0 | F6: 0 | G6: 0 | H6: 0 | I6: 0 | J6: 0 | K6: 0 | L6: 0 | M6: 0 | N6: 0 | O6: 0 | P6: 0 | Q6: 0 | R6: 0 | S6: 0 | T6: 0 | U6: 0 | V6: 0 | W6: 0 | X6: 0 | Y6: 0 | Z6: 0
A7: 4 | B7: 0 | C7: 0 | D7: 0 | E7: 0 | F7: 0 | G7: 0 | H7: 0 | I7: 0 | J7: 0 | K7: 0 | L7: 0 | M7: 0 | N7: 0 | O7: 0 | P7: 0 | Q7: 0 | R7: 0 | S7: 0 | T7: 0 | U7: 0 | V7: 0 | W7: 0 | X7: 0 | Y7: 0 | Z7: 0
A8: 5 | B8: 0 | C8: 0 | D8: 0 | E8: 0 | F8: 0 | G8: 0 | H8: 0 | I8: 0 | J8: 0 | K8: 0 | L8: 0 | M8: 0 | N8: 0 | O8: 0 | P8: 0 | Q8: 0 | R8: 0 | S8: 0 | T8: 0 | U8: 0 | V8: 0 | W8: 0 | X8: 0 | Y8: 0 | Z8: 0
A9: 6 | B9: 0 | C9: 0 | D9: 0 | E9: 0 | F9: 0 | G9: 0 | H9: 0 | I9: 0 | J9: 0 | K9: 0 | L9: 0 | M9: 0 | N9: 0 | O9: 0 | P9: 0 | Q9: 0 | R9: 0 | S9: 0 | T9: 0 | U9: 0 | V9: 0 | W9: 0 | X9: 0 | Y9: 0 | Z9: 0
A10: 7 | B10: 0 | C10: 0 | D10: 0 | E10: 0 | F10: 0 | G10: 0 | H10: 0 | I10: 0 | J10: 0 | K10: 0 | L10: 0 | M10: 0 | N10: 0 | O10: 0 | P10: 0 | Q10: 0 | R10: 0 | S10: 0 | T10: 0 | U10: 0 | V10: 0 | W10: 0 | X10: 0 | Y10: 0 | Z10: 0
A11: 8 | B11: 0 | C11: 0 | D11: 0 | E11: 0 | F11: 0 | G11: 0 | H11: 0 | I11: 0 | J11: 0 | K11: 0 | L11: 0 | M11: 0 | N11: 0 | O11: 0 | P11: 0 | Q11: 0 | R11: 0 | S11: 0 | T11: 0 | U11: 0 | V11: 0 | W11: 0 | X11: 0 | Y11: 0 | Z11: 0
A12: 9 | B12: 0 | C12: 0 | D12: 0 | E12: 0 | F12: 0 | G12: 0 | H12: 0 | I12: 0 | J12: 0 | K12: 0 | L12: 0 | M12: 0 | N12: 0 | O12: 0 | P12: 0 | Q12: 0 | R12: 0 | S12: 0 | T12: 0 | U12: 0 | V12: 0 | W12: 0 | X12: 0 | Y12: 0 | Z12: 0
A13: 10 | B13: 0 | C13: 0 | D13: 0 | E13: 0 | F13: 0 | G13: 0 | H13: 0 | I13: 0 | J13: 0 | K13: 0 | L13: 0 | M13: 0 | N13: 0 | O13: 0 | P13: 0 | Q13: 0 | R13: 0 | S13: 0 | T13: 0 | U13: 0 | V13: 0 | W13: 0 | X13: 0 | Y13: 0 | Z13: 0
A14: 11 | B14: 0 | C14: 0 | D14: 0 | E14: 0 | F14: 0 | G14: 0 | H14: 0 | I14: 0 | J14: 0 | K14: 0 | L14: 0 | M14: 0 | N14: 0 | O14: 0 | P14: 0 | Q14: 0 | R14: 0 | S14: 0 | T14: 0 | U14: 0 | V14: 0 | W14: 0 | X14: 0 | Y14: 0 | Z14: 0
A15: 12 | B15: 0 | C15: 0 | D15: 0 | E15: 0 | F15: 0 | G15: 0 | H15: 0 | I15: 0 | J15: 0 | K15: 0 | L15: 0 | M15: 0 | N15: 0 | O15: 0 | P15: 0 | Q15: 0 | R15: 0 | S15: 0 | T15: 0 | U15: 0 | V15: 0 | W15: 0 | X15: 0 | Y15: 0 | Z15: 0
... A59: 56 | B59: 0 | C59: 0 | D59: 0 | E59: 0 | F59: 0 | G59: 0 | H59: 0 | I59: 0 | J59: 0 | K59: 0 | L59: 0 | M59: 0 | N59: 0 | O59: 0 | P59: 0 | Q59: 0 | R59: 0 | S59: 0 | T59: 0 | U59: 0 | V59: 0 | W59: 0 | X59: 0 | Y59: 0 | Z59: 0

Sheet Friday
A1: Friday
B2: 180 | I2: Black Out | M2: Ball Return | Y2: Other
A3: Lane | B3: Ball Blocking Pins | C3: Pin Guide Jam | D3: Turn Pan Jam | E3: Pin Gate Locked | F3: Pin Head First | G3: Turret Jam | H3: Other | I3: Deck Jam | J3: Turn Pan Jam | K3: Electrical | L3: Other | M3: Pins Blocking Ball | N3: Spinning | O3: Under Elbow | P3: In Pin Wheel | Q3: Between Lift Rod & Pit Cushion | R3: Yo-Yo | S3: Top Of Lift Rod | T3: Locked @ Pref | U3: Pin in Return Track | V3: @Y | W3: In Front of Pit Cushion | X3: Other | Y3: Respot | Z3: Other
A4: 1 | B4: 0 | C4: 0 | D4: 0 | E4: 0 | F4: 0 | G4: 0 | H4: 0 | I4: 0 | J4: 0 | K4: 0 | L4: 0 | M4: 0 | N4: 0 | O4: 0 | P4: 0 | Q4: 0 | R4: 0 | S4: 0 | T4: 0 | U4: 0 | V4: 0 | W4: 0 | X4: 0 | Y4: 0 | Z4: 0
A5: 2 | B5: 0 | C5: 0 | D5: 0 | E5: 0 | F5: 0 | G5: 0 | H5: 0 | I5: 0 | J5: 0 | K5: 0 | L5: 0 | M5: 0 | N5: 0 | O5: 0 | P5: 0 | Q5: 0 | R5: 0 | S5: 0 | T5: 0 | U5: 0 | V5: 0 | W5: 0 | X5: 0 | Y5: 0 | Z5: 0
A6: 3 | B6: 0 | C6: 0 | D6: 0 | E6: 0 | F6: 0 | G6: 0 | H6: 0 | I6: 0 | J6: 0 | K6: 0 | L6: 0 | M6: 0 | N6: 0 | O6: 0 | P6: 0 | Q6: 0 | R6: 0 | S6: 0 | T6: 0 | U6: 0 | V6: 0 | W6: 0 | X6: 0 | Y6: 0 | Z6: 0
A7: 4 | B7: 0 | C7: 0 | D7: 0 | E7: 0 | F7: 0 | G7: 0 | H7: 0 | I7: 0 | J7: 0 | K7: 0 | L7: 0 | M7: 0 | N7: 0 | O7: 0 | P7: 0 | Q7: 0 | R7: 0 | S7: 0 | T7: 0 | U7: 0 | V7: 0 | W7: 0 | X7: 0 | Y7: 0 | Z7: 0
A8: 5 | B8: 0 | C8: 0 | D8: 0 | E8: 0 | F8: 0 | G8: 0 | H8: 0 | I8: 0 | J8: 0 | K8: 0 | L8: 0 | M8: 0 | N8: 0 | O8: 0 | P8: 0 | Q8: 0 | R8: 0 | S8: 0 | T8: 0 | U8: 0 | V8: 0 | W8: 0 | X8: 0 | Y8: 0 | Z8: 0
A9: 6 | B9: 0 | C9: 0 | D9: 0 | E9: 0 | F9: 0 | G9: 0 | H9: 0 | I9: 0 | J9: 0 | K9: 0 | L9: 0 | M9: 0 | N9: 0 | O9: 0 | P9: 0 | Q9: 0 | R9: 0 | S9: 0 | T9: 0 | U9: 0 | V9: 0 | W9: 0 | X9: 0 | Y9: 0 | Z9: 0
A10: 7 | B10: 0 | C10: 0 | D10: 0 | E10: 0 | F10: 0 | G10: 0 | H10: 0 | I10: 0 | J10: 0 | K10: 0 | L10: 0 | M10: 0 | N10: 0 | O10: 0 | P10: 0 | Q10: 0 | R10: 0 | S10: 0 | T10: 0 | U10: 0 | V10: 0 | W10: 0 | X10: 0 | Y10: 0 | Z10: 0
A11: 8 | B11: 0 | C11: 0 | D11: 0 | E11: 0 | F11: 0 | G11: 0 | H11: 0 | I11: 0 | J11: 0 | K11: 0 | L11: 0 | M11: 0 | N11: 0 | O11: 0 | P11: 0 | Q11: 0 | R11: 0 | S11: 0 | T11: 0 | U11: 0 | V11: 0 | W11: 0 | X11: 0 | Y11: 0 | Z11: 0
A12: 9 | B12: 0 | C12: 0 | D12: 0 | E12: 0 | F12: 0 | G12: 0 | H12: 0 | I12: 0 | J12: 0 | K12: 0 | L12: 0 | M12: 0 | N12: 0 | O12: 0 | P12: 0 | Q12: 0 | R12: 0 | S12: 0 | T12: 0 | U12: 0 | V12: 0 | W12: 0 | X12: 0 | Y12: 0 | Z12: 0
A13: 10 | B13: 0 | C13: 0 | D13: 0 | E13: 0 | F13: 0 | G13: 0 | H13: 0 | I13: 0 | J13: 0 | K13: 0 | L13: 0 | M13: 0 | N13: 0 | O13: 0 | P13: 0 | Q13: 0 | R13: 0 | S13: 0 | T13: 0 | U13: 0 | V13: 0 | W13: 0 | X13: 0 | Y13: 0 | Z13: 0
A14: 11 | B14: 0 | C14: 0 | D14: 0 | E14: 0 | F14: 0 | G14: 0 | H14: 0 | I14: 0 | J14: 0 | K14: 0 | L14: 0 | M14: 0 | N14: 0 | O14: 0 | P14: 0 | Q14: 0 | R14: 0 | S14: 0 | T14: 0 | U14: 0 | V14: 0 | W14: 0 | X14: 0 | Y14: 0 | Z14: 0
A15: 12 | B15: 0 | C15: 0 | D15: 0 | E15: 0 | F15: 0 | G15: 0 | H15: 0 | I15: 0 | J15: 0 | K15: 0 | L15: 0 | M15: 0 | N15: 0 | O15: 0 | P15: 0 | Q15: 0 | R15: 0 | S15: 0 | T15: 0 | U15: 0 | V15: 0 | W15: 0 | X15: 0 | Y15: 0 | Z15: 0
... A59: 56 | B59: 0 | C59: 0 | D59: 0 | E59: 0 | F59: 0 | G59: 0 | H59: 0 | I59: 0 | J59: 0 | K59: 0 | L59: 0 | M59: 0 | N59: 0 | O59: 0 | P59: 0 | Q59: 0 | R59: 0 | S59: 0 | T59: 0 | U59: 0 | V59: 0 | W59: 0 | X59: 0 | Y59: 0 | Z59: 0

Sheet Saturday
A1: Saturday
B2: 180 | I2: Black Out | M2: Ball Return | Y2: Other
A3: Lane | B3: Ball Blocking Pins | C3: Pin Guide Jam | D3: Turn Pan Jam | E3: Pin Gate Locked | F3: Pin Head First | G3: Turret Jam | H3: Other | I3: Deck Jam | J3: Turn Pan Jam | K3: Electrical | L3: Other | M3: Pins Blocking Ball | N3: Spinning | O3: Under Elbow | P3: In Pin Wheel | Q3: Between Lift Rod & Pit Cushion | R3: Yo-Yo | S3: Top Of Lift Rod | T3: Locked @ Pref | U3: Pin in Return Track | V3: @Y | W3: In Front of Pit Cushion | X3: Other | Y3: Respot | Z3: Other
A4: 1 | B4: 0 | C4: 0 | D4: 0 | E4: 0 | F4: 0 | G4: 0 | H4: 0 | I4: 0 | J4: 0 | K4: 0 | L4: 0 | M4: 0 | N4: 0 | O4: 0 | P4: 0 | Q4: 0 | R4: 0 | S4: 0 | T4: 0 | U4: 0 | V4: 0 | W4: 0 | X4: 0 | Y4: 0 | Z4: 0
A5: 2 | B5: 0 | C5: 0 | D5: 0 | E5: 0 | F5: 0 | G5: 0 | H5: 0 | I5: 0 | J5: 0 | K5: 0 | L5: 0 | M5: 0 | N5: 0 | O5: 0 | P5: 0 | Q5: 0 | R5: 0 | S5: 0 | T5: 0 | U5: 0 | V5: 0 | W5: 0 | X5: 0 | Y5: 0 | Z5: 0
A6: 3 | B6: 0 | C6: 0 | D6: 0 | E6: 0 | F6: 0 | G6: 0 | H6: 0 | I6: 0 | J6: 0 | K6: 0 | L6: 0 | M6: 0 | N6: 0 | O6: 0 | P6: 0 | Q6: 0 | R6: 0 | S6: 0 | T6: 0 | U6: 0 | V6: 0 | W6: 0 | X6: 0 | Y6: 0 | Z6: 0
A7: 4 | B7: 0 | C7: 0 | D7: 0 | E7: 0 | F7: 0 | G7: 0 | H7: 0 | I7: 0 | J7: 0 | K7: 0 | L7: 0 | M7: 0 | N7: 0 | O7: 0 | P7: 0 | Q7: 0 | R7: 0 | S7: 0 | T7: 0 | U7: 0 | V7: 0 | W7: 0 | X7: 0 | Y7: 0 | Z7: 0
A8: 5 | B8: 0 | C8: 0 | D8: 0 | E8: 0 | F8: 0 | G8: 0 | H8: 0 | I8: 0 | J8: 0 | K8: 0 | L8: 0 | M8: 0 | N8: 0 | O8: 0 | P8: 0 | Q8: 0 | R8: 0 | S8: 0 | T8: 0 | U8: 0 | V8: 0 | W8: 0 | X8: 0 | Y8: 0 | Z8: 0
A9: 6 | B9: 0 | C9: 0 | D9: 0 | E9: 0 | F9: 0 | G9: 0 | H9: 0 | I9: 0 | J9: 0 | K9: 0 | L9: 0 | M9: 0 | N9: 0 | O9: 0 | P9: 0 | Q9: 0 | R9: 0 | S9: 0 | T9: 0 | U9: 0 | V9: 0 | W9: 0 | X9: 0 | Y9: 0 | Z9: 0
A10: 7 | B10: 0 | C10: 0 | D10: 0 | E10: 0 | F10: 0 | G10: 0 | H10: 0 | I10: 0 | J10: 0 | K10: 0 | L10: 0 | M10: 0 | N10: 0 | O10: 0 | P10: 0 | Q10: 0 | R10: 0 | S10: 0 | T10: 0 | U10: 0 | V10: 0 | W10: 0 | X10: 0 | Y10: 0 | Z10: 0
A11: 8 | B11: 0 | C11: 0 | D11: 0 | E11: 0 | F11: 0 | G11: 0 | H11: 0 | I11: 0 | J11: 0 | K11: 0 | L11: 0 | M11: 0 | N11: 0 | O11: 0 | P11: 0 | Q11: 0 | R11: 0 | S11: 0 | T11: 0 | U11: 0 | V11: 0 | W11: 0 | X11: 0 | Y11: 0 | Z11: 0
A12: 9 | B12: 0 | C12: 0 | D12: 0 | E12: 0 | F12: 0 | G12: 0 | H12: 0 | I12: 0 | J12: 0 | K12: 0 | L12: 0 | M12: 0 | N12: 0 | O12: 0 | P12: 0 | Q12: 0 | R12: 0 | S12: 0 | T12: 0 | U12: 0 | V12: 0 | W12: 0 | X12: 0 | Y12: 0 | Z12: 0
A13: 10 | B13: 0 | C13: 0 | D13: 0 | E13: 0 | F13: 0 | G13: 0 | H13: 0 | I13: 0 | J13: 0 | K13: 0 | L13: 0 | M13: 0 | N13: 0 | O13: 0 | P13: 0 | Q13: 0 | R13: 0 | S13: 0 | T13: 0 | U13: 0 | V13: 0 | W13: 0 | X13: 0 | Y13: 0 | Z13: 0
A14: 11 | B14: 0 | C14: 0 | D14: 0 | E14: 0 | F14: 0 | G14: 0 | H14: 0 | I14: 0 | J14: 0 | K14: 0 | L14: 0 | M14: 0 | N14: 0 | O14: 0 | P14: 0 | Q14: 0 | R14: 0 | S14: 0 | T14: 0 | U14: 0 | V14: 0 | W14: 0 | X14: 0 | Y14: 0 | Z14: 0
A15: 12 | B15: 0 | C15: 0 | D15: 0 | E15: 0 | F15: 0 | G15: 0 | H15: 0 | I15: 0 | J15: 0 | K15: 0 | L15: 0 | M15: 0 | N15: 0 | O15: 0 | P15: 0 | Q15: 0 | R15: 0 | S15: 0 | T15: 0 | U15: 0 | V15: 0 | W15: 0 | X15: 0 | Y15: 0 | Z15: 0
... A59: 56 | B59: 0 | C59: 0 | D59: 0 | E59: 0 | F59: 0 | G59: 0 | H59: 0 | I59: 0 | J59: 0 | K59: 0 | L59: 0 | M59: 0 | N59: 0 | O59: 0 | P59: 0 | Q59: 0 | R59: 0 | S59: 0 | T59: 0 | U59: 0 | V59: 0 | W59: 0 | X59: 0 | Y59: 0 | Z59: 0

Sheet Sunday
A1: Sunday
B2: 180 | I2: Black Out | M2: Ball Return | Y2: Other
A3: Lane | B3: Ball Blocking Pins | C3: Pin Guide Jam | D3: Turn Pan Jam | E3: Pin Gate Locked | F3: Pin Head First | G3: Turret Jam | H3: Other | I3: Deck Jam | J3: Turn Pan Jam | K3: Electrical | L3: Other | M3: Pins Blocking Ball | N3: Spinning | O3: Under Elbow | P3: In Pin Wheel | Q3: Between Lift Rod & Pit Cushion | R3: Yo-Yo | S3: Top Of Lift Rod | T3: Locked @ Pref | U3: Pin in Return Track | V3: @Y | W3: In Front of Pit Cushion | X3: Other | Y3: Respot | Z3: Other
A4: 1 | B4: 0 | C4: 0 | D4: 0 | E4: 0 | F4: 0 | G4: 0 | H4: 0 | I4: 0 | J4: 0 | K4: 0 | L4: 0 | M4: 0 | N4: 0 | O4: 0 | P4: 0 | Q4: 0 | R4: 0 | S4: 0 | T4: 0 | U4: 0 | V4: 0 | W4: 0 | X4: 0 | Y4: 0 | Z4: 0
A5: 2 | B5: 0 | C5: 0 | D5: 0 | E5: 0 | F5: 0 | G5: 0 | H5: 0 | I5: 0 | J5: 0 | K5: 0 | L5: 0 | M5: 0 | N5: 0 | O5: 0 | P5: 0 | Q5: 0 | R5: 0 | S5: 0 | T5: 0 | U5: 0 | V5: 0 | W5: 0 | X5: 0 | Y5: 0 | Z5: 0
A6: 3 | B6: 0 | C6: 0 | D6: 0 | E6: 0 | F6: 0 | G6: 0 | H6: 0 | I6: 0 | J6: 0 | K6: 0 | L6: 0 | M6: 0 | N6: 0 | O6: 0 | P6: 0 | Q6: 0 | R6: 0 | S6: 0 | T6: 0 | U6: 0 | V6: 0 | W6: 0 | X6: 0 | Y6: 0 | Z6: 0
A7: 4 | B7: 0 | C7: 0 | D7: 0 | E7: 0 | F7: 0 | G7: 0 | H7: 0 | I7: 0 | J7: 0 | K7: 0 | L7: 0 | M7: 0 | N7: 0 | O7: 0 | P7: 0 | Q7: 0 | R7: 0 | S7: 0 | T7: 0 | U7: 0 | V7: 0 | W7: 0 | X7: 0 | Y7: 0 | Z7: 0
A8: 5 | B8: 0 | C8: 0 | D8: 0 | E8: 0 | F8: 0 | G8: 0 | H8: 0 | I8: 0 | J8: 0 | K8: 0 | L8: 0 | M8: 0 | N8: 0 | O8: 0 | P8: 0 | Q8: 0 | R8: 0 | S8: 0 | T8: 0 | U8: 0 | V8: 0 | W8: 0 | X8: 0 | Y8: 0 | Z8: 0
A9: 6 | B9: 0 | C9: 0 | D9: 0 | E9: 0 | F9: 0 | G9: 0 | H9: 0 | I9: 0 | J9: 0 | K9: 0 | L9: 0 | M9: 0 | N9: 0 | O9: 0 | P9: 0 | Q9: 0 | R9: 0 | S9: 0 | T9: 0 | U9: 0 | V9: 0 | W9: 0 | X9: 0 | Y9: 0 | Z9: 0
A10: 7 | B10: 0 | C10: 0 | D10: 0 | E10: 0 | F10: 0 | G10: 0 | H10: 0 | I10: 0 | J10: 0 | K10: 0 | L10: 0 | M10: 0 | N10: 0 | O10: 0 | P10: 0 | Q10: 0 | R10: 0 | S10: 0 | T10: 0 | U10: 0 | V10: 0 | W10: 0 | X10: 0 | Y10: 0 | Z10: 0
A11: 8 | B11: 0 | C11: 0 | D11: 0 | E11: 0 | F11: 0 | G11: 0 | H11: 0 | I11: 0 | J11: 0 | K11: 0 | L11: 0 | M11: 0 | N11: 0 | O11: 0 | P11: 0 | Q11: 0 | R11: 0 | S11: 0 | T11: 0 | U11: 0 | V11: 0 | W11: 0 | X11: 0 | Y11: 0 | Z11: 0
A12: 9 | B12: 0 | C12: 0 | D12: 0 | E12: 0 | F12: 0 | G12: 0 | H12: 0 | I12: 0 | J12: 0 | K12: 0 | L12: 0 | M12: 0 | N12: 0 | O12: 0 | P12: 0 | Q12: 0 | R12: 0 | S12: 0 | T12: 0 | U12: 0 | V12: 0 | W12: 0 | X12: 0 | Y12: 0 | Z12: 0
A13: 10 | B13: 0 | C13: 0 | D13: 0 | E13: 0 | F13: 0 | G13: 0 | H13: 0 | I13: 0 | J13: 0 | K13: 0 | L13: 0 | M13: 0 | N13: 0 | O13: 0 | P13: 0 | Q13: 0 | R13: 0 | S13: 0 | T13: 0 | U13: 0 | V13: 0 | W13: 0 | X13: 0 | Y13: 0 | Z13: 0
A14: 11 | B14: 0 | C14: 0 | D14: 0 | E14: 0 | F14: 0 | G14: 0 | H14: 0 | I14: 0 | J14: 0 | K14: 0 | L14: 0 | M14: 0 | N14: 0 | O14: 0 | P14: 0 | Q14: 0 | R14: 0 | S14: 0 | T14: 0 | U14: 0 | V14: 0 | W14: 0 | X14: 0 | Y14: 0 | Z14: 0
A15: 12 | B15: 0 | C15: 0 | D15: 0 | E15: 0 | F15: 0 | G15: 0 | H15: 0 | I15: 0 | J15: 0 | K15: 0 | L15: 0 | M15: 0 | N15: 0 | O15: 0 | P15: 0 | Q15: 0 | R15: 0 | S15: 0 | T15: 0 | U15: 0 | V15: 0 | W15: 0 | X15: 0 | Y15: 0 | Z15: 0
... A59: 56 | B59: 0 | C59: 0 | D59: 0 | E59: 0 | F59: 0 | G59: 0 | H59: 0 | I59: 0 | J59: 0 | K59: 0 | L59: 0 | M59: 0 | N59: 0 | O59: 0 | P59: 0 | Q59: 0 | R59: 0 | S59: 0 | T59: 0 | U59: 0 | V59: 0 | W59: 0 | X59: 0 | Y59: 0 | Z59: 0
